# gererator 错误处理

## 函数体外抛出错误，函数体内捕获错误， 相反，函数体外抛出的错误函数体内捕获

```javascript
function* gen() {
  try {
    yield 3;
  } catch (err) {
    console.log('内部错误', err)
  }
}

let $iterator = gen();
$iterator.next();
$iterator.throw(new Error('err'))


function* gen1() {
  const res = yield 3;
  console.log(res.toUpperCase())
}
try {
  iter = gen();
  iter.next(66);
} catch(err) {
  console.log('函数体外抛出错误，函数体内捕获', err);
}
```

## 如果generator内部没有try/catch，错误将由外部捕获

```javascript
function* gen() {
  yield 3;
}
let $iterator = gen();
$iterator.next();
try {
  $iterator.throw(new Error('err'))

} catch(err) {
  console.log('外部错误', err)
}
```

## 如果程序内部和外部均没有try/catch，那么直接中断程序运行

```javascript
function* gen() {
  yield 3;
}
let $iterator = gen();
$iterator.next();
$iterator.throw(new Error('err'));
console.log('end')
```

## throw抛出的错误前提条件是必须至少有一个next执行了
