# 通过问问题来学习Promise原理

## Promise构造函数的实现

* 调用了resolver中的resolve或者reject会发生什么

* promise的状态是怎么一回事儿

```javascript
  // 打印结果是什么
  new Promise((resolve, reject) => {
    setTimeout(() => {
      throw 'err';
    });
    resolve('success')
  }).then(res => {
    console.log('res', res)
  }).catch(err => {
    console.error(err);
  })
```

## then的实现

* then中return一个promise会怎么样

```javascript
  // 打印结果是什么
  const p1 = new Promise((resolve, reject) => {
    resolve('success')
  })
  p1.then(res => {
    return new Promise((resolve, reject) => {
      resolve(1)
    }).then(res1 => res1 + 1)
  }).then(res2 => {
    console.log(res2);
  })
```

* 为什么resolve传递的值会穿透

```javascript
  Promise.resolve(1)
    .then(7)
    .then(Promise.resolve(3))
    .then(console.log)
  // 结果是什么？
```

## Promise中的错误处理

* 为什么抛出的错误不会中断程序的运行

  ```javascript
  // 大家猜猜结果是什么？
   new Promise((resolve, reject) => {
    throw Error('err')
  })
  console.log('end')
  ```

* 抛出的错误何时在onRejected捕获何时又在catch中捕获呢

  ```javascript
  // 大家猜猜结果页是什么?
  Promise.reject('err')
    .then(null,null)
    .catch(err => console.log('catch error', err));
  
  // console.log('end')语句会执行吗
   Promise.reject('err')
    .then(null, (err) => console.log('then1', err))
    .then(null, (err) => console.log('then2', err))
    .catch(err => console.log('catch error', err));
  ```
  
> 结论：如果then中的第二个参数不是函数，上边reject的err信息会透传到下边，如果是函数的话，错误信息会不会透传到下面的

* 为什么错误处理catch要比onRejected更推荐用呢

```javascript
const p = new Promise((resolve, reject) => {
  resolve('success')
}).then(success => {
  throw 'occur error';
}, reason => {
  console.log('onRejeacted error', reason);
}).catch(err => {
  console.log('catch error', err)
})
```

## Promise.all是怎么做并发请求成功后统一返回的

## finally何时运行
